Workbook
Name \Convergence: "1000000.000000"
Name \IterationCount: 0
Name \WorstStream: " "

Sheet Raw Coal analysis
B1: Sample Name: | C1: PR9_B19_3AL
B2: Sample Description: | C2: Initial
B3: Reported date: | C3: 2019.10.10
B4: Reported to: | C4: Process team
B5: Sampled date: | C5: 2019.10.04
B7: Sample ID | C7: 28
B8: Initial Mass, kg
B9: TM, % | C9: 2.53
B10: IM, % | C10: 0.67
B11: Ash, ad % | C11: 15.78
B12: Vol, ad, % | C12: 19.74
B13: CSN, | C13: 7
B14: G index | C14: 71
B15: Sulphur, ad % | C15: 0.84
B16: TRD, ad % | C16: 1.44
B19: Petrograph
B20: Mean Maximum Reflactance (RoMax )
B21: Random Reflactance
B23: Vitrinite
B24: Liptinite
B25: Inertinite

Sheet Pretreatment
B2: Sample Name: | C2: ='Raw Coal analysis'!C1 -> PR9_B19_3AL
B3: Sample Description: | C3: Dry and Wet Sizing
B4: Reported date: | C4: ='Raw Coal analysis'!C3 -> 2019.10.10
B5: Reported to: | C5: ='Raw Coal analysis'!C4 -> Process team
B6: Sampled date: | C6: ='Raw Coal analysis'!C5 -> 2019.10.04
B8: Жингээр унагах туршилтын дараах шигшилт: 2 метр, 15 удаа | C8: Шигшүүр, мм | D8: Масс, кг | E8: Масс, %
B9: Анхдагч масс | D9: 276.2 | E9: -
C10: +50мм | D10: 35.6 | E10: =D10/$D$14 -> 0.13666027
B11: -50мм | D11: 224.9 | E11: =D11/$D$14 -> 0.86333973
B12: Массын алдагдал | D12: =D9-(D10+D11) -> 15.7 | E12: =D12/D9 -> 0.056842867
B14: Нийт масс, (массын алдагдалгүй): | D14: =D10+D11 -> 260.5 | E14: =D14/D9 -> 0.94315713
B15: Нийт масс: | D15: =D10+D11+D12 -> 276.2 | E15: =D15/D9 -> 1
B17: Хуурай тамблер & гараар бутлах (+50мм): | C17: Шигшүүр, мм | D17: Масс, кг | E17: Масс, % | G17: IM, % | H17: Ash, ad %
B18: Анхдагч масс | D18: 100 | E18: - | G18: - | H18: -
B19: -50мм | C19: +31.5мм | D19: 14.2 | E19: =D19/$D$28 -> 0.14300101 | G19: 0.65 | H19: 17.15
B20: -31.5мм | C20: +16мм | D20: 21.8 | E20: =D20/$D$28 -> 0.21953676 | G20: 0.57 | H20: 15.27
B21: -16мм | C21: +8мм | D21: 17.8 | E21: =D21/$D$28 -> 0.17925478 | G21: 0.53 | H21: 16.76
B22: -8мм | C22: +4.75мм | D22: 11.8 | E22: =D22/$D$28 -> 0.11883182 | G22: 0.66 | H22: 14.99
B23: -4.75мм | C23: +2мм | D23: 11.2 | E23: =D23/$D$28 -> 0.11278953 | G23: 0.68 | H23: 13.1
B24: -2мм | C24: +1мм | D24: 7.8 | E24: =D24/$D$28 -> 0.078549849 | G24: 0.61 | H24: 11.94
B25: -1мм | C25: 0мм | D25: 14.7 | E25: =D25/$D$28 -> 0.14803625 | G25: 0.62 | H25: 12.85
B26: Массын алдагдал | D26: =D18-SUM(D19:D25) -> 0.7 | E26: =D26/D18 -> 0.007
B28: Нийт масс, (массын алдагдалгүй): | D28: =SUM(D19:D25) -> 99.3 | E28: =D28/D18 -> 0.993
B29: Нийт масс: | D29: =SUM(D19:D25)+D26 -> 100 | E29: =D29/D18 -> 1
B31: Нойтон тамблер: | C31: Шигшүүр, мм | D31: Масс, кг | E31: Масс, % | G31: IM, % | H31: Ash, ad % | I31: Vol, ad % | J31: Sulphur, ad % | K31: CSN
B32: Анхдагч масс | D32: 50 | E32: - | G32: - | H32: - | I32: - | J32: - | K32: -
B33: -50мм | C33: +31.5мм | D33: 6.6 | E33: =D33/$D$47 -> 0.13319879 | G33: 0.57 | H33: 24.14 | I33: 19.65 | J33: 4.24 | K33: 3.5 | L33: 0.13319879 | M33: =L33*100 -> 13.319879
B34: -31.5мм | C34: +16мм | D34: 10.5 | E34: =D34/$D$47 -> 0.21190716 | G34: 0.58 | H34: 16.86 | I34: 18.93 | J34: 1.56 | K34: 4.5 | L34: 0.21190716 | M34: =L34*100 -> 21.190716
B35: -16мм | C35: +8мм | D35: 8.7 | E35: =D35/$D$47 -> 0.17558022 | G35: 0.58 | H35: 19.02 | I35: 18.65 | J35: 1.02 | K35: 4.5 | L35: 0.17558022 | M35: =L35*100 -> 17.558022
B36: -8мм | C36: +4.75мм | D36: 4.8 | E36: =D36/$D$47 -> 0.096871847 | G36: 0.59 | H36: 16.27 | I36: 19.37 | J36: 0.79 | K36: 5 | L36: 0.096871847 | M36: =L36*100 -> 9.6871847
B37: -4.75мм | C37: +2мм | D37: 5.5 | E37: =D37/$D$47 -> 0.11099899 | G37: 0.61 | H37: 14.91 | I37: 19.82 | J37: 0.9 | K37: 7 | L37: 0.11099899 | M37: =L37*100 -> 11.099899
B38: -2мм | C38: +1мм | D38: 4.2 | E38: =D38/$D$47 -> 0.084762866 | G38: 0.69 | H38: 12.65 | I38: 20.59 | J38: 0.74 | K38: 8 | L38: 0.084762866 | M38: =L38*100 -> 8.4762866
B39: -1мм | C39: +0.5мм | D39: 3.3 | E39: =D39/$D$47 -> 0.066599395 | G39: 0.63 | H39: 12.03 | I39: 21.3 | J39: 0.69 | K39: 8 | L39: 0.066599395 | M39: =L39*100 -> 6.6599395
B40: -0.5мм | C40: +0.25мм | D40: 3.2 | E40: =D40/$D$47 -> 0.064581231 | G40: 0.65 | H40: 12.77 | I40: 21.29 | J40: 1.06 | K40: 8.5 | L40: 0.064581231 | M40: =L40*100 -> 6.4581231
B41: -0.25мм | C41: +0.15мм | D41: 1.01 | E41: =D41/$D$47 -> 0.020383451 | G41: 0.7 | H41: 12.58 | I41: 21.43 | J41: 0.92 | K41: 8.5 | L41: 0.020383451 | M41: =L41*100 -> 2.0383451
B42: -0.15мм | C42: +0.074мм | D42: 1.07 | E42: =D42/$D$47 -> 0.021594349 | G42: 0.63 | H42: 13.58 | I42: 21.13 | J42: 0.95 | K42: 8.5 | L42: 0.021594349 | M42: =L42*100 -> 2.1594349
B43: -0.074мм | C43: +0.038мм | D43: 0.15 | E43: =D43/$D$47 -> 0.0030272452 | G43: 0.49 | H43: 15.4 | I43: 20.93 | J43: 1.54 | K43: 8.5 | L43: 0.0030272452 | M43: =L43*100 -> 0.30272452
B44: -0.038мм | D44: 0.52 | E44: =D44/$D$47 -> 0.01049445 | G44: 0.73 | H44: 14.09 | I44: 19.69 | J44: 0.94 | K44: 5.5 | L44: 0.01049445 | M44: =L44*100 -> 1.049445
B45: Массын алдагдал | D45: =D32-SUM(D33:D44) -> 0.45 | E45: =D45/D32 -> 0.009
B47: Нийт масс, (массын алдагдалгүй): | D47: =SUM(D33:D44) -> 49.55 | E47: =D47/D32 -> 0.991
...

Sheet Float sink
B1: Sample Name: | E1: ='Raw Coal analysis'!C1 -> PR9_B19_3AL
B2: Sample Description: | E2: Float and Sink
B3: Reported date: | E3: ='Raw Coal analysis'!C3 -> 2019.10.10
B4: Reported to: | E4: ='Raw Coal analysis'!C4 -> Process team
B5: Sampled date: | E5: ='Raw Coal analysis'!C5 -> 2019.10.04
G7: Individual
B8: Size Fraction, mm | D8: Mass % of overall | E8: Density Fraction | G8: Mass | I8: Ash, ad % | J8: IM, | K8: Vol, ad % | L8: Sulphur, ad % | M8: CSN
E9: Sink | F9: Float | G9: gram | H9: (%) | I9: (%) | J9: % | K9: %
B10: -50 | C10: +16 | G10: 5000
E11: 1.25 | F11: 1.3 | G11: 139.8 | H11: =G11/$G$25*100 -> 2.84233 | I11: 9.57 | J11: 0.49 | K11: 21.35 | L11: 0.44 | M11: 8.5
E12: =F11 -> 1.3 | F12: 1.325 | G12: 414.3 | H12: =G12/$G$25*100 -> 8.4232998 | I12: 11.63 | J12: 0.49 | K12: 21.22 | L12: 0.43 | M12: 8
E13: =F12 -> 1.325 | F13: 1.35 | G13: 1258.8 | H13: =G13/$G$25*100 -> 25.593169 | I13: 11.99 | J13: 0.49 | K13: 20.26 | L13: 0.43 | M13: 7
E14: =F13 -> 1.35 | F14: 1.375 | G14: 1157.4 | H14: =G14/$G$25*100 -> 23.531565 | I14: 15.13 | J14: 0.5 | K14: 18.7 | L14: 0.5 | M14: 4
E15: =F14 -> 1.375 | F15: 1.4 | G15: 971.8 | H15: =G15/$G$25*100 -> 19.758056 | I15: 16.75 | J15: 0.53 | K15: 18.03 | L15: 0.56 | M15: 3.5
E16: =F15 -> 1.4 | F16: 1.425 | G16: 300.8 | H16: =G16/$G$25*100 -> 6.1156857 | I16: 20.06 | J16: 0.51 | K16: 17.66 | L16: 0.68 | M16: 2
E17: =F16 -> 1.425 | F17: 1.45 | G17: 227.7 | H17: =G17/$G$25*100 -> 4.6294602 | I17: 22.06 | J17: 0.46 | K17: 17.55 | L17: 0.52 | M17: 1
E18: =F17 -> 1.45 | F18: 1.5 | G18: 277 | H18: =G18/$G$25*100 -> 5.6317983 | I18: 22.03 | J18: 0.49 | K18: 17.52 | L18: 0.45 | M18: 1
E19: =F18 -> 1.5 | F19: 1.6 | G19: 91.5 | H19: =G19/$G$25*100 -> 1.8603233 | I19: 25.56 | J19: 0.64 | K19: 18.76 | L19: 3.42 | M19: 1
E20: =F19 -> 1.6 | F20: 1.7 | G20: 14.4 | H20: =G20/$G$25*100 -> 0.29277219 | I20: 37.55 | J20: 0.68 | K20: - | L20: - | M20: 0.5
E21: =F20 -> 1.7 | F21: 1.8 | G21: - | H21: -
E22: =F21 -> 1.8 | F22: 2 | G22: - | H22: -
E23: =F22 -> 2 | F23: 2.2 | G23: 15.7 | H23: =G23/$G$25*100 -> 0.31920301 | I23: 39.95 | J23: 0.42 | K23: 28.43 | L23: 11.25 | M23: 1
E24: =F23 -> 2.2 | F24: 2.8 | G24: 49.3 | H24: =G24/$G$25*100 -> 1.0023381 | I24: 44.4 | J24: 0.37 | K24: 31.13 | L24: 8.17 | M24: 1
B25: Total | G25: =SUM(G11:G24) -> 4918.5 | H25: =SUM(H11:H24) -> 100 | I25: =SUMPRODUCT($H$11:$H$24,I11:I24)/$H$25 -> 15.836807 | J25: =SUMPRODUCT($H$11:$H$24,J11:J24)/$H$25 -> 0.50201118 | K25: =SUMPRODUCT($H$11:$H$24,K11:K24)/$H$25 -> 19.173183 | L25: =SUMPRODUCT($H$11:$H$24,L11:L24)/$H$25 -> 0.65950737 | M25: =SUMPRODUCT($H$11:$H$24,M11:M24)/$H$25 -> 4.5979872
B26: -16 | C26: +8 | G26: 5000
E27: 1.25 | F27: 1.3 | G27: 327.1 | H27: =G27/$G$41*100 -> 6.8853011 | I27: 8.28 | J27: 0.59 | K27: 21.75 | L27: 0.4 | M27: 9
E28: =F27 -> 1.3 | F28: 1.325 | G28: 899.4 | H28: =G28/$G$41*100 -> 18.931947 | I28: 9.63 | J28: 0.58 | K28: 21.3 | L28: 0.47 | M28: 8
E29: =F28 -> 1.325 | F29: 1.35 | G29: 847.3 | H29: =G29/$G$41*100 -> 17.835266 | I29: 12.31 | J29: 0.57 | K29: 19.81 | L29: 0.47 | M29: 7
E30: =F29 -> 1.35 | F30: 1.375 | G30: 853.2 | H30: =G30/$G$41*100 -> 17.959459 | I30: 14.86 | J30: 0.59 | K30: 18.69 | L30: 0.52 | M30: 4
E31: =F30 -> 1.375 | F31: 1.4 | G31: 877 | H31: =G31/$G$41*100 -> 18.460437 | I31: 17.74 | J31: 0.55 | K31: 17.76 | L31: 0.7 | M31: 3
E32: =F31 -> 1.4 | F32: 1.425 | G32: 231.3 | H32: =G32/$G$41*100 -> 4.8687562 | I32: 20.12 | J32: 0.61 | K32: 17.36 | L32: 0.84 | M32: 1
E33: =F32 -> 1.425 | F33: 1.45 | G33: 236.7 | H33: =G33/$G$41*100 -> 4.9824236 | I33: 22.05 | J33: 0.59 | K33: 17.16 | L33: 0.95 | M33: 1
E34: =F33 -> 1.45 | F34: 1.5 | G34: 219.8 | H34: =G34/$G$41*100 -> 4.6266866 | I34: 24.04 | J34: 0.59 | K34: 17.02 | L34: 1.96 | M34: 1
E35: =F34 -> 1.5 | F35: 1.6 | G35: 91.5 | H35: =G35/$G$41*100 -> 1.926032 | I35: 29.64 | J35: 0.76 | K35: 16.99 | L35: 3.28 | M35: 1
E36: =F35 -> 1.6 | F36: 1.7 | G36: 59 | H36: =G36/$G$41*100 -> 1.2419222 | I36: 35.97 | J36: 0.88 | K36: 18.1 | L36: 6.51 | M36: 1
E37: =F36 -> 1.7 | F37: 1.8 | G37: 15.1 | H37: =G37/$G$41*100 -> 0.3178479 | I37: 41.93 | J37: 0.92 | K37: 18.71 | L37: 5.92 | M37: 0.5
E38: =F37 -> 1.8 | F38: 2 | G38: 17.7 | H38: =G38/$G$41*100 -> 0.37257667 | I38: 44.36 | J38: 0.88 | K38: 20.4 | L38: 7.72 | M38: 0.5
E39: =F38 -> 2 | F39: 2.2 | G39: 20.1 | H39: =G39/$G$41*100 -> 0.42309554 | I39: 56.68 | J39: 1.19 | K39: 20.46 | L39: 9.01 | M39: 0
E40: =F39 -> 2.2 | F40: 2.8 | G40: 55.5 | H40: =G40/$G$41*100 -> 1.1682489 | I40: 70.76 | J40: 1.24 | K40: 18.12 | L40: 5.24 | M40: 0
B41: Total | G41: =SUM(G27:G40) -> 4750.7 | H41: =SUM(H27:H40) -> 100 | I41: =SUMPRODUCT($H$27:$H$40,I27:I40)/$H$41 -> 16.105509 | J41: =SUMPRODUCT($H$27:$H$40,J27:J40)/$H$41 -> 0.59726672 | K41: =SUMPRODUCT($H$27:$H$40,K27:K40)/$H$41 -> 19.17183 | L41: =SUMPRODUCT($H$27:$H$40,L27:L40)/$H$41 -> 0.89281264 | M41: =SUMPRODUCT($H$27:$H$40,M27:M40)/$H$41 -> 4.8348033
...

Sheet Froth Flotation
B1: Sample Name: | D1: ='Raw Coal analysis'!C1 -> PR9_B19_3AL
B2: Sample Description: | D2: -0.25мм Froth Flotation
B3: Reported date: | D3: ='Raw Coal analysis'!C3 -> 2019.10.10
B4: Reported to: | D4: ='Raw Coal analysis'!C4 -> Process team
B5: Sampled date: | D5: ='Raw Coal analysis'!C5 -> 2019.10.04
B7: Size Fraction, mm | D7: Mass % of overall | E7: fraction | F7: Mass | H7: Ash, ad % | I7: IM, | J7: Vol, ad % | K7: Sulphur, ad % | L7: CSN
F8: gram | G8: (%) | H8: (%) | I8: % | J8: %
B9: -0.25 | C9: +0 | F9: 350
E10: C1 | F10: 142.6 | G10: =F10/$F$16*100 -> 40.789474 | H10: 8.75 | I10: 0.81 | J10: 21.99 | K10: 0.93 | L10: 8.5
E11: C2 | F11: 122 | G11: =F11/$F$16*100 -> 34.897025 | H11: 10.67 | I11: 0.49 | J11: 21.22 | K11: 0.92 | L11: 7.5
E12: C3 | F12: 55.8 | G12: =F12/$F$16*100 -> 15.961098 | H12: 11.5 | I12: 0.89 | J12: 21.05 | K12: 1.11 | L12: 7
E13: C4 | F13: 6.4 | G13: =F13/$F$16*100 -> 1.8306636 | H13: 21.19 | I13: 0.75 | J13: - | K13: 2.5 | L13: 1.5
E14: T1 | F14: 20.1 | G14: =F14/$F$16*100 -> 5.7494279 | H14: 55.73 | I14: 0.61 | J14: 17.8 | K14: 2.4 | L14: 1
E15: T2 | F15: 2.7 | G15: =F15/$F$16*100 -> 0.77231121 | H15: 46.15 | I15: 0.83 | J15: - | K15: - | L15: -
B16: Total | F16: =SUM(F10:F15) -> 349.6 | G16: =SUM(G10:G15) -> 100 | H16: =SUMPRODUCT($G$10:$G$15,H10:H15)/$G$16 -> 13.076613 | I16: =SUMPRODUCT($G$10:$G$15,I10:I15)/$G$16 -> 0.69865561 | J16: =SUMPRODUCT($G$10:$G$15,J10:J15)/$G$16 -> 20.757963 | K16: =SUMPRODUCT($G$10:$G$15,K10:K15)/$G$16 -> 1.0613158 | L16: =SUMPRODUCT($G$10:$G$15,L10:L15)/$G$16 -> 7.2866133

Sheet Composite Product Analysis 
B1: Sample Name: | C1: ='Raw Coal analysis'!C1 -> PR9_B19_3AL
B2: Sample Description: | C2: Composite Product Analysis
B3: Reported date: | C3: ='Raw Coal analysis'!C3 -> 2019.10.10
B4: Reported to: | C4: ='Raw Coal analysis'!C4 -> Process team
B5: Sampled date: | C5: ='Raw Coal analysis'!C5 -> 2019.10.04
B8: Sample ID | C8: 28
B9: Initial Mass, kg
B10: TM, %
B11: IM, %
B12: Ash, ad %
B13: Vol, ad, %
B14: CSN,
B15: G index
B16: Sulphur, ad %
B17: TRD, ad %
B20: Petrograph
B21: Mean Maximum Reflactance (RoMax )
B22: Random Reflactance
... B26: Inertinite
