Workbook
Name \Convergence: "1000000.000000"
Name \IterationCount: 0
Name \WorstStream: " "

Sheet Instruction
B1: Version 2 | L1: Washability test Flowchart (In-Pt sample)
B2: 43674
I44: 1/8 шинжилгээнд | R44: Нойтон тамблер
P51: +0.5мм | W51: -0.5 мм
Y55: 1/10 шинжилгээнд | AF55: 9/10 Float & Sink
J56: 1/10 шинжилгээнд | Q56: 9/10 Float & Sink

Sheet Inst.Eng
B2: Version 2 | L2: Washability test Flowchart
B3: 43674
I54: 1/8 For analysis | Q54: Wet tumbler
P60: +0.5mm | W60: -0.5 mm
Y64: 1/10 For analysis. | AF64: 9/10 Float & Sink
J65: 1/10 For analysis | Q65: 9/10 Float & Sink

Sheet Raw Coal analysis
B1: Sample Name: | C1: PR8_B35_4AL_01-08
B2: Sample Description: | C2: #19_20
B3: Reported date:
B4: Reported to:
B5: Sampled date: | C5: 43668
B7: Sample ID | C7: =C1 -> PR8_B35_4AL_01-08
B8: Initial Mass, kg | C8: 288
B9: TM, % | C9: 1.67
B10: IM, % | C10: 0.9
B11: Ash, ad % | C11: 24.76
B12: Ash, d % | C12: =C11*100/(100-C10) -> 24.984864
B13: Vol, ad, % | C13: 21.81
B14: Vol, daf, % | C14: =C13*100/(100-C10-C11) -> 29.338176
B15: CSN, | C15: 5.5
B16: G index | C16: 61
B17: Sulphur, ad % | C17: 0.59
B18: Sulphur, d % | C18: =C17*100/(100-C10) -> 0.59535822
B19: TRD | C19: 1.49
B22: Petrograph
B23: Mean Maximum Reflactance (RoMax )
B24: Random Reflactance
B26: Vitrinite
B27: Liptinite
B28: Inertinite

Sheet Pretreatment
B2: Sample Name: | C2: ='[1]Raw Coal analysis'!C1 -> PR8_B35_4AL_01-08 | X2: Girdlines
B3: Sample Description: | C3: Dry and Wet Sizing | X3: MinSize | Z3: 0.01 | AA3: =LN(-LN(1-AB3/100)) -> 1.5271796 | AB3: 99
B4: Reported date: | C4: ='[1]Raw Coal analysis'!C3 -> 0 | X4: MaxSize | Z4: 1000 | AA4: =LN(-LN(1-AB3/100)) -> 1.5271796
B5: Reported to: | C5: ='[1]Raw Coal analysis'!C4 -> 0
B6: Sampled date: | C6: ='[1]Raw Coal analysis'!C5 -> 43668 | Z6: 0.01 | AA6: =LN(-LN(1-AB6/100)) -> 1.0971887 | AB6: 95
Z14: 1000 | AA14: =LN(-LN(1-AB6/100)) -> 1.0971887
B15: Жингээр унагах туршилтын дараах шигшилт: 2 метр, 15 удаа | C15: Шигшүүр, мм | D15: Масс, кг | E15: Масс, %
B16: Анхдагч масс | D16: 288 | E16: - | Z16: 0.01 | AA16: =LN(-LN(1-AB16/100)) -> 0.83403245 | AB16: 90
C17: +50мм | D17: 10 | E17: =D17/$D$21 -> 0.034482759 | Z17: 1000 | AA17: =LN(-LN(1-AB16/100)) -> 0.83403245
B18: -50мм | D18: 280 | E18: =D18/$D$21 -> 0.96551724
B19: Массын алдагдал | D19: =D16-(D17+D18) -> -2 | E19: =D19/D16 -> -0.0069444444 | Z19: 0.01 | AA19: =LN(-LN(1-AB19/100)) -> 0.475885 | AB19: 80
Z20: 1000 | AA20: =LN(-LN(1-AB19/100)) -> 0.475885
B21: Нийт масс, (массын алдагдалгүй): | D21: =D17+D18 -> 290 | E21: =D21/D16 -> 1.0069444
B22: Нийт масс: | D22: =D17+D18+D19 -> 288 | E22: =D22/D16 -> 1 | Z22: 0.01 | AA22: =LN(-LN(1-AB22/100)) -> 0.18562676 | AB22: 70
Q23: After Dry Tumbler | Z23: 1000 | AA23: =LN(-LN(1-AB22/100)) -> 0.18562676
B24: Хуурай тамблер & гараар бутлах (+50мм): | C24: Шигшүүр, мм | D24: Масс, кг | E24: Масс, % | G24: Mass, % exc.loss | H24: IM, % | I24: Ash, ad % | J24: Ash, d % | Q24: Size, mm | R24: Passing, % | S24: Cumulative | T24: ln(-ln(1-y/100)) | U24: ln X
B25: Анхдагч масс | D25: 100 | E25: - | H25: - | I25: - | Z25: 0.01 | AA25: =LN(-LN(1-AB25/100)) -> -0.087421572 | AB25: 60
B26: -50мм | C26: +31.5мм | D26: 10.6 | E26: =D26/$D$25 -> 0.106 | G26: =D26/$D$35*100 -> 10.6 | H26: 0.81 | I26: 31.9 | J26: =I26*100/(100-H26) -> 32.1605 | Q26: 50 | R26: =G26 -> 10.6 | S26: =SUM(R26:$R$32) -> 100 | T26: n/a | U26: =LN(Q26) -> 3.912023 | Z26: 1000 | AA26: =LN(-LN(1-AB25/100)) -> -0.087421572
B27: -31.5мм | C27: +16мм | D27: 16 | E27: =D27/$D$25 -> 0.16 | G27: =D27/$D$35*100 -> 16 | H27: 0.88 | I27: 32.01 | J27: =I27*100/(100-H27) -> 32.294189 | Q27: 31.5 | R27: =G27 -> 16 | S27: =SUM(R27:$R$32) -> 89.4 | T27: =LN(-LN(1-S27/100)) -> 0.80840088 | U27: =LN(Q27) -> 3.4499875
B28: -16мм | C28: +8мм | D28: 17 | E28: =D28/$D$25 -> 0.17 | G28: =D28/$D$35*100 -> 17 | H28: 0.86 | I28: 29.22 | J28: =I28*100/(100-H28) -> 29.473472 | Q28: 16 | R28: =G28 -> 17 | S28: =SUM(R28:$R$32) -> 73.4 | T28: =LN(-LN(1-S28/100)) -> 0.28085304 | U28: =LN(Q28) -> 2.7725887 | Z28: 0.01 | AA28: =LN(-LN(1-AB28/100)) -> -0.36651292 | AB28: 50
B29: -8мм | C29: +4.75мм | D29: 13 | E29: =D29/$D$25 -> 0.13 | G29: =D29/$D$35*100 -> 13 | H29: 0.76 | I29: 23.06 | J29: =I29*100/(100-H29) -> 23.236598 | Q29: 8 | R29: =G29 -> 13 | S29: =SUM(R29:$R$32) -> 56.4 | T29: =LN(-LN(1-S29/100)) -> -0.1861934 | U29: =LN(Q29) -> 2.0794415 | Z29: 1000 | AA29: =LN(-LN(1-AB28/100)) -> -0.36651292
B30: -4.75мм | C30: +2мм | D30: 16 | E30: =D30/$D$25 -> 0.16 | G30: =D30/$D$35*100 -> 16 | H30: 0.81 | I30: 22.15 | J30: =I30*100/(100-H30) -> 22.33088 | Q30: 4.75 | R30: =G30 -> 16 | S30: =SUM(R30:$R$32) -> 43.4 | T30: =LN(-LN(1-S30/100)) -> -0.56359158 | U30: =LN(Q30) -> 1.5581446
B31: -2мм | C31: +1мм | D31: 9.4 | E31: =D31/$D$25 -> 0.094 | G31: =D31/$D$35*100 -> 9.4 | H31: 0.81 | I31: 19.95 | J31: =I31*100/(100-H31) -> 20.112915 | Q31: 2 | R31: =G31 -> 9.4 | S31: =SUM(R31:$R$32) -> 27.4 | T31: =LN(-LN(1-S31/100)) -> -1.138793 | U31: =LN(Q31) -> 0.69314718 | Z31: 0.01 | AA31: =LN(-LN(1-AB31/100)) -> -0.67172699 | AB31: 40
B32: -1мм | C32: 0мм | D32: 18 | E32: =D32/$D$25 -> 0.18 | G32: =D32/$D$35*100 -> 18 | H32: 0.78 | I32: 20.86 | J32: =I32*100/(100-H32) -> 21.023987 | Q32: 1 | R32: =G32 -> 18 | S32: =SUM(R32:$R$32) -> 18 | T32: =LN(-LN(1-S32/100)) -> -1.6172134 | U32: =LN(Q32) -> 0 | Z32: 1000 | AA32: =LN(-LN(1-AB31/100)) -> -0.67172699
B33: Массын алдагдал | D33: =D25-SUM(D26:D32) -> 0 | E33: =D33/$D$25 -> 0 | G33: =SUM(G26:G32) -> 100 | H33: =SUMPRODUCT(H26:H32,$G$26:$G$32)/$G$33 -> 0.8178 | I33: =SUMPRODUCT(I26:I32,$G$26:$G$32)/$G$33 -> 25.6423 | J33: =SUMPRODUCT(J26:J32,$G$26:$G$32)/$G$33 -> 25.855204
Z34: 0.01 | AA34: =LN(-LN(1-AB34/100)) -> -1.0309304 | AB34: 30
B35: Нийт масс, (массын алдагдалгүй): | D35: =SUM(D26:D32) -> 100 | E35: =D35/D25 -> 1 | Z35: 1000 | AA35: =LN(-LN(1-AB34/100)) -> -1.0309304
B36: Нийт масс: | D36: =SUM(D26:D32)+D33 -> 100 | E36: =D36/D25 -> 1
Q37: After Wet Tumbler | Z37: 0.01 | AA37: =LN(-LN(1-AB37/100)) -> -1.49994 | AB37: 20
B38: Нойтон тамблер: | C38: Шигшүүр, мм | D38: Масс, кг | E38: Масс, % | G38: Mass, % exc.loss | H38: IM, % | I38: Ash, ad % | J38: Ash, d % | K38: Vol, % ad | L38: Vol, % daf | M38: Sulphur, ad % | N38: Sulphur, d % | O38: CSN | Q38: Size, mm | R38: Passing, % | S38: Cumulative | T38: ln(-ln(1-y/100)) | U38: ln X | Z38: 1000 | AA38: =LN(-LN(1-AB37/100)) -> -1.49994
B39: Анхдагч масс | D39: 50 | E39: - | H39: - | I39: - | K39: - | M39: - | O39: -
B40: -50мм | C40: +31.5мм | D40: 4.3 | E40: =D40/$D$39 -> 0.086 | G40: =D40/$D$54*100 -> 8.9958159 | H40: 0.72 | I40: 32.47 | J40: =I40*100/(100-H40) -> 32.705479 | M40: 0.52 | N40: =M40*100/(100-H40) -> 0.52377115 | O40: 0.5 | Q40: 50 | R40: =G40 -> 8.9958159 | S40: =SUM(R40:$R$51) -> 100 | T40: n/a | U40: =LN(Q40) -> 3.912023 | Z40: 0.01 | AA40: =LN(-LN(1-AB40/100)) -> -1.8169608 | AB40: 15
B41: -31.5мм | C41: +16мм | D41: 6.7 | E41: =D41/$D$39 -> 0.134 | G41: =D41/$D$54*100 -> 14.016736 | H41: 0.8 | I41: 28.02 | J41: =I41*100/(100-H41) -> 28.245968 | M41: 0.55 | N41: =M41*100/(100-H41) -> 0.55443548 | O41: 1 | Q41: 31.5 | R41: =G41 -> 14.016736 | S41: =SUM(R41:$R$51) -> 91.004184 | T41: =LN(-LN(1-S41/100)) -> 0.87896703 | U41: =LN(Q41) -> 3.4499875 | Z41: 1000 | AA41: =LN(-LN(1-AB40/100)) -> -1.8169608
B42: -16мм | C42: +8мм | D42: 7.9 | E42: =D42/$D$39 -> 0.158 | G42: =D42/$D$54*100 -> 16.527197 | H42: 0.75 | I42: 27.46 | J42: =I42*100/(100-H42) -> 27.667506 | M42: 0.46 | N42: =M42*100/(100-H42) -> 0.46347607 | O42: 1 | Q42: 16 | R42: =G42 -> 16.527197 | S42: =SUM(R42:$R$51) -> 76.987448 | T42: =LN(-LN(1-S42/100)) -> 0.38467064 | U42: =LN(Q42) -> 2.7725887
B43: -8мм | C43: +4.75мм | D43: 6.3 | E43: =D43/$D$39 -> 0.126 | G43: =D43/$D$54*100 -> 13.179916 | H43: 0.68 | I43: 24.79 | J43: =I43*100/(100-H43) -> 24.959726 | M43: 0.52 | N43: =M43*100/(100-H43) -> 0.52356021 | O43: 2.5 | Q43: 8 | R43: =G43 -> 13.179916 | S43: =SUM(R43:$R$51) -> 60.460251 | T43: =LN(-LN(1-S43/100)) -> -0.074870413 | U43: =LN(Q43) -> 2.0794415 | Z43: 0.01 | AA43: =LN(-LN(1-AB43/100)) -> -2.2503673 | AB43: 10
B44: -4.75мм | C44: +2мм | D44: 8.4 | E44: =D44/$D$39 -> 0.168 | G44: =D44/$D$54*100 -> 17.573222 | H44: 0.78 | I44: 25.74 | J44: =I44*100/(100-H44) -> 25.94235 | M44: 0.65 | N44: =M44*100/(100-H44) -> 0.65510986 | O44: 4 | Q44: 4.75 | R44: =G44 -> 17.573222 | S44: =SUM(R44:$R$51) -> 47.280335 | T44: =LN(-LN(1-S44/100)) -> -0.44600332 | U44: =LN(Q44) -> 1.5581446 | Z44: 1000 | AA44: =LN(-LN(1-AB43/100)) -> -2.2503673
B45: -2мм | C45: +1мм | D45: 4 | E45: =D45/$D$39 -> 0.08 | G45: =D45/$D$54*100 -> 8.3682008 | H45: 0.84 | I45: 23.71 | J45: =I45*100/(100-H45) -> 23.910851 | M45: 0.68 | N45: =M45*100/(100-H45) -> 0.68576039 | O45: 5.5 | Q45: 2 | R45: =G45 -> 8.3682008 | S45: =SUM(R45:$R$51) -> 29.707113 | T45: =LN(-LN(1-S45/100)) -> -1.0427059 | U45: =LN(Q45) -> 0.69314718
B46: -1мм | C46: +0.5мм | D46: 2.2 | E46: =D46/$D$39 -> 0.044 | G46: =D46/$D$54*100 -> 4.6025105 | H46: 0.67 | I46: 21.44 | J46: =I46*100/(100-H46) -> 21.584617 | M46: 0.71 | N46: =M46*100/(100-H46) -> 0.71478909 | O46: 6 | Q46: 1 | R46: =G46 -> 4.6025105 | S46: =SUM(R46:$R$51) -> 21.338912 | T46: =LN(-LN(1-S46/100)) -> -1.4270264 | U46: =LN(Q46) -> 0 | Z46: 0.01 | AA46: =LN(-LN(1-AB46/100)) -> -2.4843275 | AB46: 8
B47: -0.5мм | C47: +0.25мм | D47: 3.4 | E47: =D47/$D$39 -> 0.068 | G47: =D47/$D$54*100 -> 7.1129707 | H47: 0.85 | I47: 20.51 | J47: =I47*100/(100-H47) -> 20.68583 | M47: 0.92 | N47: =M47*100/(100-H47) -> 0.92788704 | O47: 7 | Q47: 0.5 | R47: =G47 -> 7.1129707 | S47: =SUM(R47:$R$51) -> 16.736402 | T47: =LN(-LN(1-S47/100)) -> -1.6974021 | U47: =LN(Q47) -> -0.69314718 | Z47: 1000 | AA47: =LN(-LN(1-AB46/100)) -> -2.4843275
B48: -0.25мм | C48: +0.15мм | D48: 1.5 | E48: =D48/$D$39 -> 0.03 | G48: =D48/$D$54*100 -> 3.1380753 | H48: 0.81 | I48: 21.36 | J48: =I48*100/(100-H48) -> 21.534429 | M48: 0.97 | N48: =M48*100/(100-H48) -> 0.97792116 | O48: 6.5 | Q48: 0.25 | R48: =G48 -> 3.1380753 | S48: =SUM(R48:$R$51) -> 9.623431 | T48: =LN(-LN(1-S48/100)) -> -2.2908033 | U48: =LN(Q48) -> -1.3862944
...

Sheet Float sink
B1: Sample Name: | D1: ='Raw Coal analysis'!C1 -> PR8_B35_4AL_01-08
B2: Sample Description: | D2: ='Raw Coal analysis'!C2 -> #19_20
B3: Reported date:
B4: Reported to:
B5: Sampled date: | D5: ='Raw Coal analysis'!C5 -> 43668 | Q5: 1 | R5: 2 | S5: 3 | T5: 4 | U5: 5 | V5: 6 | W5: 7 | X5: 8 | Y5: 9 | Z5: 10 | AA5: 11 | AB5: 12 | AK5: 1 | AL5: 2 | AM5: 3 | AN5: 4 | AO5: 5 | AP5: 6 | AQ5: 7 | AR5: 8 | AS5: 9 | AT5: 10 | AU5: 11 | AV5: 12
G7: Individual | R7: Fractional | U7: Cum. Floats | X7: Cum. Sink | AL7: Fractional | AO7: Cum. Floats | AR7: Cum. Sink
B8: Size Fraction, mm | D8: Mass % of overall | E8: Density Fraction | G8: Mass | I8: Ash, ad | J8: IM, | K8: Vol, % ad | L8: Sulphur, ad % | M8: CSN | P8: SG | Q8: RD | R8: Mass, | S8: Ash, dry | T8: Q. of Mass, | U8: Mass, % | V8: Q. of Mass, | W8: Ash, % dry | X8: Mass, % | Y8: Q. of Mass, | Z8: Ash, % dry | AA8: Cum Mass % @ mid-density range | AB8: Near-Gravity material (Mass %) | AJ8: SG | AK8: RD | AL8: Mass, | AM8: Ash, dry | AN8: Q. of Mass, | AO8: Mass, % | AP8: Q. of Mass, | AQ8: Ash, % dry | AR8: Mass, % | AS8: Q. of Mass, | AT8: Ash, % dry | AU8: Cum Mass % @ mid-density range | AV8: Near-Gravity material (Mass %)
E9: Sink | F9: Float | G9: gram | H9: (%) | I9: (%) | J9: % | K9: % | R9: % | S9: % | T9: (2)*(3) | U9: Sum (2) â | V9: Sum (4) â | W9: (6)/(5) | X9: Sum (2) á | Y9: Sum (4) á | Z9: (9)/(8) | AA9: (5)-(2)/2 | AB9: RD+0.1 Sum (2) RD-0.1 | AL9: % | AM9: % | AN9: (2)*(3) | AO9: Sum (2) â | AP9: Sum (4) â | AQ9: (6)/(5) | AR9: Sum (2) á | AS9: Sum (4) á | AT9: (9)/(8) | AU9: (5)-(2)/2 | AV9: RD+0.1 Sum (2) RD-0.1
B10: -50 | C10: +16 | D10: =Pretreatment!R40+Pretreatment!R41 -> 23.012552 | N10: 1/RD | Q10: -50mm+16mm | AB10: =D10 -> 23.012552 | AK10: -50mm+0.25mm Composite | AV10: =AB10+AB26+AB42+AB58+AB74 -> 90.376569
E11: 1.25 | F11: 1.3 | G11: 1e-05 | H11: =G11/$G$25*100 -> 1.764353e-07 | I11: 4 | N11: =1/Q11 -> 0.76923077 | P11: 7 | Q11: 1.3 | R11: =H11 -> 1.764353e-07 | S11: =I11*100/(100-J11) -> 4 | T11: =R11*S11 -> 7.057412e-07 | U11: =SUM($R$11:R11) -> 1.764353e-07 | V11: =SUM($T$11:T11) -> 7.057412e-07 | W11: =V11/U11 -> 4 | X11: =SUM(R11:$R$24) -> 100 | Y11: =SUM(T11:$T$24) -> 3158.0872 | Z11: =Y11/X11 -> 31.580872 | AA11: =U11-R11/2 -> 8.821765e-08 | AJ11: 7 | AK11: 1.3 | AL11: =(R11*$AB$10+R27*$AB$26+R43*$AB$42+R59*$AB$58+R75*$AB$74)/$AV$10 -> 6.5624653 | AM11: =((R11*S11*$AB$10+R27*S27*$AB$26+R43*S43*$AB$42+R59*S59*$AB$58+R75*S75*$AB$74)/AL11)/$AV$10 -> 3.6154898 | AN11: =AL11*AM11 -> 23.726526 | AO11: =SUM($AL$11:AL11) -> 6.5624653 | AP11: =SUM($AN$11:AN11) -> 23.726526 | AQ11: =AP11/AO11 -> 3.6154898 | AR11: =SUM(AL11:$AL$24) -> 100 | AS11: =SUM(AN11:$AN$24) -> 2670.4952 | AT11: =AS11/AR11 -> 26.704952 | AU11: =AO11-AL11/2 -> 3.2812326
E12: =F11 -> 1.3 | F12: 1.325 | G12: 1e-05 | H12: =G12/$G$25*100 -> 1.764353e-07 | I12: 8 | N12: =1/Q12 -> 0.75471698 | P12: 14 | Q12: 1.325 | R12: =H12 -> 1.764353e-07 | S12: =I12*100/(100-J12) -> 8 | T12: =R12*S12 -> 1.4114824e-06 | U12: =SUM($R$11:R12) -> 3.528706e-07 | V12: =SUM($T$11:T12) -> 2.1172236e-06 | W12: =V12/U12 -> 6 | X12: =SUM(R12:$R$24) -> 100 | Y12: =SUM(T12:$T$24) -> 3158.0872 | Z12: =Y12/X12 -> 31.580872 | AA12: =U12-R12/2 -> 2.6465295e-07 | AJ12: 14 | AK12: 1.325 | AL12: =(R12*$AB$10+R28*$AB$26+R44*$AB$42+R60*$AB$58+R76*$AB$74)/$AV$10 -> 4.2841615 | AM12: =((R12*S12*$AB$10+R28*S28*$AB$26+R44*S44*$AB$42+R60*S60*$AB$58+R76*S76*$AB$74)/AL12)/$AV$10 -> 6.8770651 | AN12: =AL12*AM12 -> 29.462457 | AO12: =SUM($AL$11:AL12) -> 10.846627 | AP12: =SUM($AN$11:AN12) -> 53.188983 | AQ12: =AP12/AO12 -> 4.903735 | AR12: =SUM(AL12:$AL$24) -> 93.437535 | AS12: =SUM(AN12:$AN$24) -> 2646.7687 | AT12: =AS12/AR12 -> 28.326611 | AU12: =AO12-AL12/2 -> 8.704546
E13: =F12 -> 1.325 | F13: 1.35 | G13: 93.9 | H13: =G13/$G$25*100 -> 1.6567275 | I13: 11 | J13: 0.94 | K13: 23.59 | L13: 1.03 | M13: 4.5 | N13: =1/Q13 -> 0.74074074 | P13: 21 | Q13: 1.35 | R13: =H13 -> 1.6567275 | S13: =I13*100/(100-J13) -> 11.104381 | T13: =R13*S13 -> 18.396933 | U13: =SUM($R$11:R13) -> 1.6567278 | V13: =SUM($T$11:T13) -> 18.396935 | W13: =V13/U13 -> 11.10438 | X13: =SUM(R13:$R$24) -> 100 | Y13: =SUM(T13:$T$24) -> 3158.0872 | Z13: =Y13/X13 -> 31.580872 | AA13: =U13-R13/2 -> 0.82836409 | AB13: =SUM(R12:R15) -> 6.5228132 | AJ13: 21 | AK13: 1.35 | AL13: =(R13*$AB$10+R29*$AB$26+R45*$AB$42+R61*$AB$58+R77*$AB$74)/$AV$10 -> 5.2410371 | AM13: =((R13*S13*$AB$10+R29*S29*$AB$26+R45*S45*$AB$42+R61*S61*$AB$58+R77*S77*$AB$74)/AL13)/$AV$10 -> 10.922829 | AN13: =AL13*AM13 -> 57.246953 | AO13: =SUM($AL$11:AL13) -> 16.087664 | AP13: =SUM($AN$11:AN13) -> 110.43594 | AQ13: =AP13/AO13 -> 6.8646348 | AR13: =SUM(AL13:$AL$24) -> 89.153373 | AS13: =SUM(AN13:$AN$24) -> 2617.3063 | AT13: =AS13/AR13 -> 29.357344 | AU13: =AO13-AL13/2 -> 13.467145 | AV13: =SUM(AL12:AL15) -> 22.075053
E14: =F13 -> 1.35 | F14: 1.375 | G14: 96.9 | H14: =G14/$G$25*100 -> 1.7096581 | I14: 15 | J14: 1.05 | K14: 19.88 | L14: 1.43 | M14: 4 | N14: =1/Q14 -> 0.72727273 | P14: 28 | Q14: 1.375 | R14: =H14 -> 1.7096581 | S14: =I14*100/(100-J14) -> 15.159171 | T14: =R14*S14 -> 25.916999 | U14: =SUM($R$11:R14) -> 3.3663859 | V14: =SUM($T$11:T14) -> 44.313935 | W14: =V14/U14 -> 13.163653 | X14: =SUM(R14:$R$24) -> 98.343272 | Y14: =SUM(T14:$T$24) -> 3139.6903 | Z14: =Y14/X14 -> 31.925827 | AA14: =U14-R14/2 -> 2.5115569 | AB14: =SUM(R13:R16) -> 18.1746 | AJ14: 28 | AK14: 1.375 | AL14: =(R14*$AB$10+R30*$AB$26+R46*$AB$42+R62*$AB$58+R78*$AB$74)/$AV$10 -> 5.9433646 | AM14: =((R14*S14*$AB$10+R30*S30*$AB$26+R46*S46*$AB$42+R62*S62*$AB$58+R78*S78*$AB$74)/AL14)/$AV$10 -> 13.886148 | AN14: =AL14*AM14 -> 82.530442 | AO14: =SUM($AL$11:AL14) -> 22.031028 | AP14: =SUM($AN$11:AN14) -> 192.96638 | AQ14: =AP14/AO14 -> 8.7588457 | AR14: =SUM(AL14:$AL$24) -> 83.912336 | AS14: =SUM(AN14:$AN$24) -> 2560.0593 | AT14: =AS14/AR14 -> 30.508736 | AU14: =AO14-AL14/2 -> 19.059346 | AV14: =SUM(AL13:AL16) -> 27.927857
E15: =F14 -> 1.375 | F15: 1.4 | G15: 178.9 | H15: =G15/$G$25*100 -> 3.1564275 | I15: 18.06 | J15: 1.01 | K15: 22.14 | L15: 0.86 | M15: 3.5 | N15: =1/Q15 -> 0.71428571 | P15: 35 | Q15: 1.4 | R15: =H15 -> 3.1564275 | S15: =I15*100/(100-J15) -> 18.244267 | T15: =R15*S15 -> 57.586707 | U15: =SUM($R$11:R15) -> 6.5228134 | V15: =SUM($T$11:T15) -> 101.90064 | W15: =V15/U15 -> 15.622192 | X15: =SUM(R15:$R$24) -> 96.633614 | Y15: =SUM(T15:$T$24) -> 3113.7733 | Z15: =Y15/X15 -> 32.222465 | AA15: =U15-R15/2 -> 4.9445997 | AB15: =SUM(R14:R17) -> 28.159074 | AJ15: 35 | AK15: 1.4 | AL15: =(R15*$AB$10+R31*$AB$26+R47*$AB$42+R63*$AB$58+R79*$AB$74)/$AV$10 -> 6.60649 | AM15: =((R15*S15*$AB$10+R31*S31*$AB$26+R47*S47*$AB$42+R63*S63*$AB$58+R79*S79*$AB$74)/AL15)/$AV$10 -> 16.544104 | AN15: =AL15*AM15 -> 109.29845 | AO15: =SUM($AL$11:AL15) -> 28.637518 | AP15: =SUM($AN$11:AN15) -> 302.26483 | AQ15: =AP15/AO15 -> 10.554854 | AR15: =SUM(AL15:$AL$24) -> 77.968972 | AS15: =SUM(AN15:$AN$24) -> 2477.5289 | AT15: =AS15/AR15 -> 31.775831 | AU15: =AO15-AL15/2 -> 25.334273 | AV15: =SUM(AL14:AL17) -> 32.805536
E16: =F15 -> 1.4 | F16: 1.425 | G16: 660.4 | H16: =G16/$G$25*100 -> 11.651787 | I16: 19 | J16: 0.77 | K16: 21.69 | L16: 0.54 | M16: 3.5 | N16: =1/Q16 -> 0.70175439 | P16: 42 | Q16: 1.425 | R16: =H16 -> 11.651787 | S16: =I16*100/(100-J16) -> 19.147435 | T16: =R16*S16 -> 223.10184 | U16: =SUM($R$11:R16) -> 18.174601 | V16: =SUM($T$11:T16) -> 325.00248 | W16: =V16/U16 -> 17.882235 | X16: =SUM(R16:$R$24) -> 93.477187 | Y16: =SUM(T16:$T$24) -> 3056.1866 | Z16: =Y16/X16 -> 32.694465 | AA16: =U16-R16/2 -> 12.348707 | AB16: =SUM(R15:R18) -> 47.72222 | AJ16: 42 | AK16: 1.425 | AL16: =(R16*$AB$10+R32*$AB$26+R48*$AB$42+R64*$AB$58+R80*$AB$74)/$AV$10 -> 10.136965 | AM16: =((R16*S16*$AB$10+R32*S32*$AB$26+R48*S48*$AB$42+R64*S64*$AB$58+R80*S80*$AB$74)/AL16)/$AV$10 -> 18.726503 | AN16: =AL16*AM16 -> 189.82991 | AO16: =SUM($AL$11:AL16) -> 38.774484 | AP16: =SUM($AN$11:AN16) -> 492.09474 | AQ16: =AP16/AO16 -> 12.6912 | AR16: =SUM(AL16:$AL$24) -> 71.362482 | AS16: =SUM(AN16:$AN$24) -> 2368.2304 | AT16: =AS16/AR16 -> 33.185931 | AU16: =AO16-AL16/2 -> 33.706001 | AV16: =SUM(AL15:AL18) -> 43.522929
E17: =F16 -> 1.425 | F17: 1.45 | G17: 659.8 | H17: =G17/$G$25*100 -> 11.641201 | I17: 21.45 | J17: 1.03 | K17: 20.5 | L17: 0.645 | M17: 2 | N17: =1/Q17 -> 0.68965517 | P17: 49 | Q17: 1.45 | R17: =H17 -> 11.641201 | S17: =I17*100/(100-J17) -> 21.673234 | T17: =R17*S17 -> 252.30248 | U17: =SUM($R$11:R17) -> 29.815802 | V17: =SUM($T$11:T17) -> 577.30496 | W17: =V17/U17 -> 19.362383 | X17: =SUM(R17:$R$24) -> 81.825399 | Y17: =SUM(T17:$T$24) -> 2833.0847 | Z17: =Y17/X17 -> 34.623537 | AA17: =U17-R17/2 -> 23.995201 | AB17: =SUM(R16:R19) -> 62.283425 | AJ17: 49 | AK17: 1.45 | AL17: =(R17*$AB$10+R33*$AB$26+R49*$AB$42+R65*$AB$58+R81*$AB$74)/$AV$10 -> 10.118716 | AM17: =((R17*S17*$AB$10+R33*S33*$AB$26+R49*S49*$AB$42+R65*S65*$AB$58+R81*S81*$AB$74)/AL17)/$AV$10 -> 21.484371 | AN17: =AL17*AM17 -> 217.39425 | AO17: =SUM($AL$11:AL17) -> 48.8932 | AP17: =SUM($AN$11:AN17) -> 709.48899 | AQ17: =AP17/AO17 -> 14.510995 | AR17: =SUM(AL17:$AL$24) -> 61.225516 | AS17: =SUM(AN17:$AN$24) -> 2178.4005 | AT17: =AS17/AR17 -> 35.579945 | AU17: =AO17-AL17/2 -> 43.833842 | AV17: =SUM(AL16:AL19) -> 50.136472
E18: =F17 -> 1.45 | F18: 1.5 | G18: 1205.7 | H18: =G18/$G$25*100 -> 21.272804 | I18: 25.61 | J18: 0.94 | K18: 19.51 | L18: 0.48 | M18: 1 | N18: =1/Q18 -> 0.66666667 | P18: 56 | Q18: 1.5 | R18: =H18 -> 21.272804 | S18: =I18*100/(100-J18) -> 25.853018 | T18: =R18*S18 -> 549.9662 | U18: =SUM($R$11:R18) -> 51.088606 | V18: =SUM($T$11:T18) -> 1127.2712 | W18: =V18/U18 -> 22.065021 | X18: =SUM(R18:$R$24) -> 70.184198 | Y18: =SUM(T18:$T$24) -> 2580.7823 | Z18: =Y18/X18 -> 36.771557 | AA18: =U18-R18/2 -> 40.452204 | AJ18: 56 | AK18: 1.5 | AL18: =(R18*$AB$10+R34*$AB$26+R50*$AB$42+R66*$AB$58+R82*$AB$74)/$AV$10 -> 16.660758 | AM18: =((R18*S18*$AB$10+R34*S34*$AB$26+R50*S50*$AB$42+R66*S66*$AB$58+R82*S82*$AB$74)/AL18)/$AV$10 -> 25.454133 | AN18: =AL18*AM18 -> 424.08515 | AO18: =SUM($AL$11:AL18) -> 65.553958 | AP18: =SUM($AN$11:AN18) -> 1133.5741 | AQ18: =AP18/AO18 -> 17.29223 | AR18: =SUM(AL18:$AL$24) -> 51.1068 | AS18: =SUM(AN18:$AN$24) -> 1961.0062 | AT18: =AS18/AR18 -> 38.37075 | AU18: =AO18-AL18/2 -> 57.223579
E19: =F18 -> 1.5 | F19: 1.6 | G19: 1004.2 | H19: =G19/$G$25*100 -> 17.717633 | I19: 31.03 | J19: 0.89 | K19: 19.06 | L19: 0.48 | M19: 1 | N19: =1/Q19 -> 0.625 | P19: 63 | Q19: 1.6 | R19: =H19 -> 17.717633 | S19: =I19*100/(100-J19) -> 31.308647 | T19: =R19*S19 -> 554.71511 | U19: =SUM($R$11:R19) -> 68.806239 | V19: =SUM($T$11:T19) -> 1681.9863 | W19: =V19/U19 -> 24.445258 | X19: =SUM(R19:$R$24) -> 48.911394 | Y19: =SUM(T19:$T$24) -> 2030.8161 | Z19: =Y19/X19 -> 41.520306 | AA19: =U19-R19/2 -> 59.947422 | AB19: =SUM(R18:R20) -> 56.695719 | AJ19: 63 | AK19: 1.6 | AL19: =(R19*$AB$10+R35*$AB$26+R51*$AB$42+R67*$AB$58+R83*$AB$74)/$AV$10 -> 13.220033 | AM19: =((R19*S19*$AB$10+R35*S35*$AB$26+R51*S51*$AB$42+R67*S67*$AB$58+R83*S83*$AB$74)/AL19)/$AV$10 -> 31.438411 | AN19: =AL19*AM19 -> 415.61682 | AO19: =SUM($AL$11:AL19) -> 78.77399 | AP19: =SUM($AN$11:AN19) -> 1549.191 | AQ19: =AP19/AO19 -> 19.666275 | AR19: =SUM(AL19:$AL$24) -> 34.446042 | AS19: =SUM(AN19:$AN$24) -> 1536.9211 | AT19: =AS19/AR19 -> 44.61822 | AU19: =AO19-AL19/2 -> 72.163974 | AV19: =SUM(AL18:AL20) -> 38.763484
E20: =F19 -> 1.6 | F20: 1.7 | G20: 1003.5 | H20: =G20/$G$25*100 -> 17.705282 | I20: 38.79 | J20: 1.17 | K20: 16.66 | L20: 0.54 | M20: 0.5 | N20: =1/Q20 -> 0.58823529 | P20: 70 | Q20: 1.7 | R20: =H20 -> 17.705282 | S20: =I20*100/(100-J20) -> 39.249216 | T20: =R20*S20 -> 694.91845 | U20: =SUM($R$11:R20) -> 86.511521 | V20: =SUM($T$11:T20) -> 2376.9047 | W20: =V20/U20 -> 27.475008 | X20: =SUM(R20:$R$24) -> 31.193761 | Y20: =SUM(T20:$T$24) -> 1476.101 | Z20: =Y20/X20 -> 47.32039 | AA20: =U20-R20/2 -> 77.65888 | AB20: =SUM(R20:R21) -> 21.274569 | AJ20: 70 | AK20: 1.7 | AL20: =(R20*$AB$10+R36*$AB$26+R52*$AB$42+R68*$AB$58+R84*$AB$74)/$AV$10 -> 8.8826932 | AM20: =((R20*S20*$AB$10+R36*S36*$AB$26+R52*S52*$AB$42+R68*S68*$AB$58+R84*S84*$AB$74)/AL20)/$AV$10 -> 39.010451 | AN20: =AL20*AM20 -> 346.51787 | AO20: =SUM($AL$11:AL20) -> 87.656683 | AP20: =SUM($AN$11:AN20) -> 1895.7088 | AQ20: =AP20/AO20 -> 21.626518 | AR20: =SUM(AL20:$AL$24) -> 21.22601 | AS20: =SUM(AN20:$AN$24) -> 1121.3043 | AT20: =AS20/AR20 -> 52.826899 | AU20: =AO20-AL20/2 -> 83.215337 | AV20: =SUM(AL20:AL21) -> 10.903569
E21: =F20 -> 1.7 | F21: 1.8 | G21: 202.3 | H21: =G21/$G$25*100 -> 3.5692861 | I21: 42.88 | J21: 1.28 | K21: 17.36 | L21: 0.71 | M21: 0.5 | N21: =1/Q21 -> 0.55555556 | P21: 77 | Q21: 1.8 | R21: =H21 -> 3.5692861 | S21: =I21*100/(100-J21) -> 43.435981 | T21: =R21*S21 -> 155.03544 | U21: =SUM($R$11:R21) -> 90.080807 | V21: =SUM($T$11:T21) -> 2531.9402 | W21: =V21/U21 -> 28.107432 | X21: =SUM(R21:$R$24) -> 13.488479 | Y21: =SUM(T21:$T$24) -> 781.18251 | Z21: =Y21/X21 -> 57.914797 | AA21: =U21-R21/2 -> 88.296164 | AB21: =SUM(R21:R22) -> 5.7447334 | AJ21: 77 | AK21: 1.8 | AL21: =(R21*$AB$10+R37*$AB$26+R53*$AB$42+R69*$AB$58+R85*$AB$74)/$AV$10 -> 2.0208758 | AM21: =((R21*S21*$AB$10+R37*S37*$AB$26+R53*S53*$AB$42+R69*S69*$AB$58+R85*S85*$AB$74)/AL21)/$AV$10 -> 44.037674 | AN21: =AL21*AM21 -> 88.994672 | AO21: =SUM($AL$11:AL21) -> 89.677559 | AP21: =SUM($AN$11:AN21) -> 1984.7035 | AQ21: =AP21/AO21 -> 22.131551 | AR21: =SUM(AL21:$AL$24) -> 12.343317 | AS21: =SUM(AN21:$AN$24) -> 774.7864 | AT21: =AS21/AR21 -> 62.76971 | AU21: =AO21-AL21/2 -> 88.667121 | AV21: =SUM(AL21:AL22) -> 4.3091963
E22: =F21 -> 1.8 | F22: 2 | G22: 123.3 | H22: =G22/$G$25*100 -> 2.1754473 | I22: 50.06 | J22: 1.55 | K22: 17.3 | L22: 0.705 | M22: 0 | N22: =1/Q22 -> 0.5 | P22: 84 | Q22: 2 | R22: =H22 -> 2.1754473 | S22: =I22*100/(100-J22) -> 50.848146 | T22: =R22*S22 -> 110.61746 | U22: =SUM($R$11:R22) -> 92.256255 | V22: =SUM($T$11:T22) -> 2642.5576 | W22: =V22/U22 -> 28.643669 | X22: =SUM(R22:$R$24) -> 9.9191926 | Y22: =SUM(T22:$T$24) -> 626.14706 | Z22: =Y22/X22 -> 63.124801 | AA22: =U22-R22/2 -> 91.168531 | AJ22: 84 | AK22: 2 | AL22: =(R22*$AB$10+R38*$AB$26+R54*$AB$42+R70*$AB$58+R86*$AB$74)/$AV$10 -> 2.2883205 | AM22: =((R22*S22*$AB$10+R38*S38*$AB$26+R54*S54*$AB$42+R70*S70*$AB$58+R86*S86*$AB$74)/AL22)/$AV$10 -> 50.951922 | AN22: =AL22*AM22 -> 116.59433 | AO22: =SUM($AL$11:AL22) -> 91.96588 | AP22: =SUM($AN$11:AN22) -> 2101.2978 | AQ22: =AP22/AO22 -> 22.848668 | AR22: =SUM(AL22:$AL$24) -> 10.322441 | AS22: =SUM(AN22:$AN$24) -> 685.79173 | AT22: =AS22/AR22 -> 66.436975 | AU22: =AO22-AL22/2 -> 90.82172
E23: =F22 -> 2 | F23: 2.2 | G23: 137.3 | H23: =G23/$G$25*100 -> 2.4224567 | I23: 60.33 | J23: 1.31 | K23: 14.33 | L23: 0.59 | M23: 0 | N23: =1/Q23 -> 0.45454545 | P23: 91 | Q23: 2.2 | R23: =H23 -> 2.4224567 | S23: =I23*100/(100-J23) -> 61.130814 | T23: =R23*S23 -> 148.08675 | U23: =SUM($R$11:R23) -> 94.678711 | V23: =SUM($T$11:T23) -> 2790.6444 | W23: =V23/U23 -> 29.474888 | X23: =SUM(R23:$R$24) -> 7.7437453 | Y23: =SUM(T23:$T$24) -> 515.5296 | Z23: =Y23/X23 -> 66.573677 | AA23: =U23-R23/2 -> 93.467483 | AJ23: 91 | AK23: 2.2 | AL23: =(R23*$AB$10+R39*$AB$26+R55*$AB$42+R71*$AB$58+R87*$AB$74)/$AV$10 -> 2.2037986 | AM23: =((R23*S23*$AB$10+R39*S39*$AB$26+R55*S55*$AB$42+R71*S71*$AB$58+R87*S87*$AB$74)/AL23)/$AV$10 -> 59.335188 | AN23: =AL23*AM23 -> 130.76281 | AO23: =SUM($AL$11:AL23) -> 94.169678 | AP23: =SUM($AN$11:AN23) -> 2232.0606 | AQ23: =AP23/AO23 -> 23.702541 | AR23: =SUM(AL23:$AL$24) -> 8.0341202 | AS23: =SUM(AN23:$AN$24) -> 569.1974 | AT23: =AS23/AR23 -> 70.847509 | AU23: =AO23-AL23/2 -> 93.067779
E24: =F23 -> 2.2 | F24: 2.8 | G24: 301.6 | H24: =G24/$G$25*100 -> 5.3212887 | I24: 68.14 | J24: 1.32 | K24: 12.29 | L24: 0.3 | M24: 0 | N24: =1/Q24 -> 0.35714286 | P24: 98 | Q24: 2.8 | R24: =H24 -> 5.3212887 | S24: =I24*100/(100-J24) -> 69.05148 | T24: =R24*S24 -> 367.44286 | U24: =SUM($R$11:R24) -> 100 | V24: =SUM($T$11:T24) -> 3158.0872 | W24: =V24/U24 -> 31.580872 | X24: =SUM(R24:$R$24) -> 5.3212887 | Y24: =SUM(T24:$T$24) -> 367.44286 | Z24: =Y24/X24 -> 69.05148 | AA24: =U24-R24/2 -> 97.339356 | AJ24: 98 | AK24: 2.8 | AL24: =(R24*$AB$10+R40*$AB$26+R56*$AB$42+R72*$AB$58+R88*$AB$74)/$AV$10 -> 5.8303215 | AM24: =((R24*S24*$AB$10+R40*S40*$AB$26+R56*S56*$AB$42+R72*S72*$AB$58+R88*S88*$AB$74)/AL24)/$AV$10 -> 75.199043 | AN24: =AL24*AM24 -> 438.4346 | AO24: =SUM($AL$11:AL24) -> 100 | AP24: =SUM($AN$11:AN24) -> 2670.4952 | AQ24: =AP24/AO24 -> 26.704952 | AR24: =SUM(AL24:$AL$24) -> 5.8303215 | AS24: =SUM(AN24:$AN$24) -> 438.4346 | AT24: =AS24/AR24 -> 75.199043 | AU24: =AO24-AL24/2 -> 97.084839
B25: Total | G25: =SUM(G11:G24) -> 5667.8 | H25: =SUM(H11:H24) -> 100 | I25: =SUMPRODUCT($H$11:$H$24,I11:I24)/$H$25 -> 31.240175 | J25: =SUMPRODUCT($H$11:$H$24,J11:J24)/$H$25 -> 1.0212123 | K25: =SUMPRODUCT($H$11:$H$24,K11:K24)/$H$25 -> 18.817364 | L25: =SUMPRODUCT($H$11:$H$24,L11:L24)/$H$25 -> 0.5603609 | M25: =SUMPRODUCT($H$11:$H$24,M11:M24)/$H$25 -> 1.3903278 | O25: =COUNT(O11:O24) -> 0 | P25: 100
B26: -16 | C26: +8 | D26: =Pretreatment!R42 -> 16.527197 | N26: 1/RD | Q26: -16+8mm | AB26: =D26 -> 16.527197 | AK26: -50mm+8.0mm Composite | AV26: =AB10+AB26 -> 39.539749
E27: 1.25 | F27: 1.3 | G27: 13.5 | H27: =G27/$G$41*100 -> 0.45308095 | I27: 6.03 | J27: 0.96 | K27: 29.61 | L27: 0.67 | M27: 7 | N27: =1/Q27 -> 0.76923077 | P27: 7 | Q27: 1.3 | R27: =H27 -> 0.45308095 | S27: =I27*100/(100-J27) -> 6.0884491 | T27: =R27*S27 -> 2.7585603 | U27: =SUM($R$27:R27) -> 0.45308095 | V27: =SUM($T$27:T27) -> 2.7585603 | W27: =V27/U27 -> 6.0884491 | X27: =SUM(R27:$R$40) -> 100 | Y27: =SUM(T27:$T$40) -> 2617.4847 | Z27: =Y27/X27 -> 26.174847 | AA27: =U27-R27/2 -> 0.22654048 | AJ27: 7 | AK27: 1.3 | AL27: =(R11*$AB$10+R27*$AB$26)/$AV$26 -> 0.18938315 | AM27: =((R11*S11*$AB$10+R27*S27*$AB$26)/AL27)/$AV$26 -> 6.088448 | AN27: =AL27*AM27 -> 1.1530494 | AO27: =SUM($AL$27:AL27) -> 0.18938315 | AP27: =SUM($AN$27:AN27) -> 1.1530494 | AQ27: =AP27/AO27 -> 6.088448 | AR27: =SUM(AL27:$AL$40) -> 100 | AS27: =SUM(AN27:$AN$40) -> 2932.1211 | AT27: =AS27/AR27 -> 29.321211 | AU27: =AO27-AL27/2 -> 0.094691573
E28: =F27 -> 1.3 | F28: 1.325 | G28: 30.7 | H28: =G28/$G$41*100 -> 1.0303396 | I28: 9.39 | J28: 0.85 | K28: 27.98 | L28: 0.66 | M28: 6.5 | N28: =1/Q28 -> 0.75471698 | P28: 14 | Q28: 1.325 | R28: =H28 -> 1.0303396 | S28: =I28*100/(100-J28) -> 9.4704992 | T28: =R28*S28 -> 9.7578308 | U28: =SUM($R$27:R28) -> 1.4834206 | V28: =SUM($T$27:T28) -> 12.516391 | W28: =V28/U28 -> 8.4375201 | X28: =SUM(R28:$R$40) -> 99.546919 | Y28: =SUM(T28:$T$40) -> 2614.7261 | Z28: =Y28/X28 -> 26.266268 | AA28: =U28-R28/2 -> 0.96825077 | AJ28: 14 | AK28: 1.325 | AL28: =(R12*$AB$10+R28*$AB$26)/$AV$26 -> 0.43067117 | AM28: =((R12*S12*$AB$10+R28*S28*$AB$26)/AL28)/$AV$26 -> 9.4704989 | AN28: =AL28*AM28 -> 4.0786708 | AO28: =SUM($AL$27:AL28) -> 0.62005432 | AP28: =SUM($AN$27:AN28) -> 5.2317203 | AQ28: =AP28/AO28 -> 8.4375193 | AR28: =SUM(AL28:$AL$40) -> 99.810617 | AS28: =SUM(AN28:$AN$40) -> 2930.968 | AT28: =AS28/AR28 -> 29.365293 | AU28: =AO28-AL28/2 -> 0.40471873
E29: =F28 -> 1.325 | F29: 1.35 | G29: 99.9 | H29: =G29/$G$41*100 -> 3.352799 | I29: 11.76 | J29: 0.85 | K29: 26.82 | L29: 0.61 | M29: 6.5 | N29: =1/Q29 -> 0.74074074 | P29: 21 | Q29: 1.35 | R29: =H29 -> 3.352799 | S29: =I29*100/(100-J29) -> 11.860817 | T29: =R29*S29 -> 39.766936 | U29: =SUM($R$27:R29) -> 4.8362196 | V29: =SUM($T$27:T29) -> 52.283327 | W29: =V29/U29 -> 10.810784 | X29: =SUM(R29:$R$40) -> 98.516579 | Y29: =SUM(T29:$T$40) -> 2604.9683 | Z29: =Y29/X29 -> 26.441928 | AA29: =U29-R29/2 -> 3.1598201 | AB29: =SUM(R28:R31) -> 21.080011 | AJ29: 21 | AK29: 1.35 | AL29: =(R13*$AB$10+R29*$AB$26)/$AV$26 -> 2.3656674 | AM29: =((R13*S13*$AB$10+R29*S29*$AB$26)/AL29)/$AV$26 -> 11.552498 | AN29: =AL29*AM29 -> 27.329368 | AO29: =SUM($AL$27:AL29) -> 2.9857218 | AP29: =SUM($AN$27:AN29) -> 32.561088 | AQ29: =AP29/AO29 -> 10.9056 | AR29: =SUM(AL29:$AL$40) -> 99.379946 | AS29: =SUM(AN29:$AN$40) -> 2926.8894 | AT29: =AS29/AR29 -> 29.451509 | AU29: =AO29-AL29/2 -> 1.802888 | AV29: =SUM(AL28:AL31) -> 12.607568
E30: =F29 -> 1.35 | F30: 1.375 | G30: 202.4 | H30: =G30/$G$41*100 -> 6.7928581 | I30: 15.1 | J30: 0.83 | K30: 24.76 | L30: 0.61 | M30: 5.5 | N30: =1/Q30 -> 0.72727273 | P30: 28 | Q30: 1.375 | R30: =H30 -> 6.7928581 | S30: =I30*100/(100-J30) -> 15.226379 | T30: =R30*S30 -> 103.43063 | U30: =SUM($R$27:R30) -> 11.629078 | V30: =SUM($T$27:T30) -> 155.71396 | W30: =V30/U30 -> 13.390052 | X30: =SUM(R30:$R$40) -> 95.16378 | Y30: =SUM(T30:$T$40) -> 2565.2013 | Z30: =Y30/X30 -> 26.955648 | AA30: =U30-R30/2 -> 8.2326487 | AB30: =SUM(R29:R32) -> 33.333333 | AJ30: 28 | AK30: 1.375 | AL30: =(R14*$AB$10+R30*$AB$26)/$AV$26 -> 3.8343819 | AM30: =((R14*S14*$AB$10+R30*S30*$AB$26)/AL30)/$AV$26 -> 15.208938 | AN30: =AL30*AM30 -> 58.316877 | AO30: =SUM($AL$27:AL30) -> 6.8201036 | AP30: =SUM($AN$27:AN30) -> 90.877966 | AQ30: =AP30/AO30 -> 13.325012 | AR30: =SUM(AL30:$AL$40) -> 97.014278 | AS30: =SUM(AN30:$AN$40) -> 2899.56 | AT30: =AS30/AR30 -> 29.887972 | AU30: =AO30-AL30/2 -> 4.9029127 | AV30: =SUM(AL29:AL32) -> 24.51079
E31: =F30 -> 1.375 | F31: 1.4 | G31: 295.1 | H31: =G31/$G$41*100 -> 9.904014 | I31: 16.75 | J31: 0.82 | K31: 23.55 | L31: 0.59 | M31: 5 | N31: =1/Q31 -> 0.71428571 | P31: 35 | Q31: 1.4 | R31: =H31 -> 9.904014 | S31: =I31*100/(100-J31) -> 16.888486 | T31: =R31*S31 -> 167.2638 | U31: =SUM($R$27:R31) -> 21.533092 | V31: =SUM($T$27:T31) -> 322.97776 | W31: =V31/U31 -> 14.999135 | X31: =SUM(R31:$R$40) -> 88.370922 | Y31: =SUM(T31:$T$40) -> 2461.7707 | Z31: =Y31/X31 -> 27.857248 | AA31: =U31-R31/2 -> 16.581085 | AB31: =SUM(R30:R33) -> 43.515908 | AJ31: 35 | AK31: 1.4 | AL31: =(R15*$AB$10+R31*$AB$26)/$AV$26 -> 5.9768473 | AM31: =((R15*S15*$AB$10+R31*S31*$AB$26)/AL31)/$AV$26 -> 17.305205 | AN31: =AL31*AM31 -> 103.43057 | AO31: =SUM($AL$27:AL31) -> 12.796951 | AP31: =SUM($AN$27:AN31) -> 194.30854 | AQ31: =AP31/AO31 -> 15.183971 | AR31: =SUM(AL31:$AL$40) -> 93.179896 | AS31: =SUM(AN31:$AN$40) -> 2841.2431 | AT31: =AS31/AR31 -> 30.492018 | AU31: =AO31-AL31/2 -> 9.8085273 | AV31: =SUM(AL30:AL33) -> 34.578068
E32: =F31 -> 1.4 | F32: 1.425 | G32: 395.8 | H32: =G32/$G$41*100 -> 13.283662 | I32: 19.19 | J32: 0.82 | K32: 21.9 | L32: 0.53 | M32: 4 | N32: =1/Q32 -> 0.70175439 | P32: 42 | Q32: 1.425 | R32: =H32 -> 13.283662 | S32: =I32*100/(100-J32) -> 19.348659 | T32: =R32*S32 -> 257.02105 | U32: =SUM($R$27:R32) -> 34.816754 | V32: =SUM($T$27:T32) -> 579.99881 | W32: =V32/U32 -> 16.658612 | X32: =SUM(R32:$R$40) -> 78.466908 | Y32: =SUM(T32:$T$40) -> 2294.5069 | Z32: =Y32/X32 -> 29.241714 | AA32: =U32-R32/2 -> 28.174923 | AB32: =SUM(R31:R34) -> 59.716069 | AJ32: 42 | AK32: 1.425 | AL32: =(R16*$AB$10+R32*$AB$26)/$AV$26 -> 12.333894 | AM32: =((R16*S16*$AB$10+R32*S32*$AB$26)/AL32)/$AV$26 -> 19.238021 | AN32: =AL32*AM32 -> 237.27971 | AO32: =SUM($AL$27:AL32) -> 25.130845 | AP32: =SUM($AN$27:AN32) -> 431.58825 | AQ32: =AP32/AO32 -> 17.173647 | AR32: =SUM(AL32:$AL$40) -> 87.203049 | AS32: =SUM(AN32:$AN$40) -> 2737.8125 | AT32: =AS32/AR32 -> 31.395835 | AU32: =AO32-AL32/2 -> 18.963898 | AV32: =SUM(AL31:AL34) -> 52.735522
E33: =F32 -> 1.425 | F33: 1.45 | G33: 403.3 | H33: =G33/$G$41*100 -> 13.535374 | I33: 22.14 | J33: 0.83 | K33: 20.27 | L33: 0.53 | M33: 2 | N33: =1/Q33 -> 0.68965517 | P33: 49 | Q33: 1.45 | R33: =H33 -> 13.535374 | S33: =I33*100/(100-J33) -> 22.3253 | T33: =R33*S33 -> 302.18128 | U33: =SUM($R$27:R33) -> 48.352128 | V33: =SUM($T$27:T33) -> 882.18009 | W33: =V33/U33 -> 18.244907 | X33: =SUM(R33:$R$40) -> 65.183246 | Y33: =SUM(T33:$T$40) -> 2037.4859 | Z33: =Y33/X33 -> 31.257815 | AA33: =U33-R33/2 -> 41.584441 | AB33: =SUM(R32:R35) -> 64.314002 | AJ33: 49 | AK33: 1.45 | AL33: =(R17*$AB$10+R33*$AB$26)/$AV$26 -> 12.432945 | AM33: =((R17*S17*$AB$10+R33*S33*$AB$26)/AL33)/$AV$26 -> 21.969958 | AN33: =AL33*AM33 -> 273.15129 | AO33: =SUM($AL$27:AL33) -> 37.56379 | AP33: =SUM($AN$27:AN33) -> 704.73954 | AQ33: =AP33/AO33 -> 18.76114 | AR33: =SUM(AL33:$AL$40) -> 74.869155 | AS33: =SUM(AN33:$AN$40) -> 2500.5328 | AT33: =AS33/AR33 -> 33.398705 | AU33: =AO33-AL33/2 -> 31.347317 | AV33: =SUM(AL32:AL35) -> 63.132185
E34: =F33 -> 1.45 | F34: 1.5 | G34: 685.1 | H34: =G34/$G$41*100 -> 22.993019 | I34: 25.4 | J34: 0.64 | K34: 19.73 | L34: 0.53 | M34: 1.5 | N34: =1/Q34 -> 0.66666667 | P34: 56 | Q34: 1.5 | R34: =H34 -> 22.993019 | S34: =I34*100/(100-J34) -> 25.563607 | T34: =R34*S34 -> 587.78451 | U34: =SUM($R$27:R34) -> 71.345147 | V34: =SUM($T$27:T34) -> 1469.9646 | W34: =V34/U34 -> 20.603568 | X34: =SUM(R34:$R$40) -> 51.647872 | Y34: =SUM(T34:$T$40) -> 1735.3046 | Z34: =Y34/X34 -> 33.598762 | AA34: =U34-R34/2 -> 59.848637 | AJ34: 56 | AK34: 1.5 | AL34: =(R18*$AB$10+R34*$AB$26)/$AV$26 -> 21.991836 | AM34: =((R18*S18*$AB$10+R34*S34*$AB$26)/AL34)/$AV$26 -> 25.72654 | AN34: =AL34*AM34 -> 565.77385 | AO34: =SUM($AL$27:AL34) -> 59.555626 | AP34: =SUM($AN$27:AN34) -> 1270.5134 | AQ34: =AP34/AO34 -> 21.333222 | AR34: =SUM(AL34:$AL$40) -> 62.43621 | AS34: =SUM(AN34:$AN$40) -> 2227.3815 | AT34: =AS34/AR34 -> 35.674515 | AU34: =AO34-AL34/2 -> 48.559708
E35: =F34 -> 1.5 | F35: 1.6 | G35: 432.1 | H35: =G35/$G$41*100 -> 14.501947 | I35: 31.65 | J35: 0.79 | K35: 18.57 | L35: 0.52 | M35: 1 | N35: =1/Q35 -> 0.625 | P35: 63 | Q35: 1.6 | R35: =H35 -> 14.501947 | S35: =I35*100/(100-J35) -> 31.902026 | T35: =R35*S35 -> 462.64148 | U35: =SUM($R$27:R35) -> 85.847094 | V35: =SUM($T$27:T35) -> 1932.6061 | W35: =V35/U35 -> 22.51219 | X35: =SUM(R35:$R$40) -> 28.654853 | Y35: =SUM(T35:$T$40) -> 1147.5201 | Z35: =Y35/X35 -> 40.046273 | AA35: =U35-R35/2 -> 78.59612 | AB35: =SUM(R34:R36) -> 45.16378 | AJ35: 63 | AK35: 1.6 | AL35: =(R19*$AB$10+R35*$AB$26)/$AV$26 -> 16.37351 | AM35: =((R19*S19*$AB$10+R35*S35*$AB$26)/AL35)/$AV$26 -> 31.528323 | AN35: =AL35*AM35 -> 516.22931 | AO35: =SUM($AL$27:AL35) -> 75.929136 | AP35: =SUM($AN$27:AN35) -> 1786.7427 | AQ35: =AP35/AO35 -> 23.531714 | AR35: =SUM(AL35:$AL$40) -> 40.444374 | AS35: =SUM(AN35:$AN$40) -> 1661.6077 | AT35: =AS35/AR35 -> 41.083778 | AU35: =AO35-AL35/2 -> 67.742381 | AV35: =SUM(AL34:AL36) -> 51.875491
E36: =F35 -> 1.6 | F36: 1.7 | G36: 228.5 | H36: =G36/$G$41*100 -> 7.6688146 | I36: 39.15 | J36: 0.86 | K36: 17.34 | L36: 0.44 | M36: 1 | N36: =1/Q36 -> 0.58823529 | P36: 70 | Q36: 1.7 | R36: =H36 -> 7.6688146 | S36: =I36*100/(100-J36) -> 39.489611 | T36: =R36*S36 -> 302.8385 | U36: =SUM($R$27:R36) -> 93.515908 | V36: =SUM($T$27:T36) -> 2235.4446 | W36: =V36/U36 -> 23.904431 | X36: =SUM(R36:$R$40) -> 14.152906 | Y36: =SUM(T36:$T$40) -> 684.87859 | Z36: =Y36/X36 -> 48.391374 | AA36: =U36-R36/2 -> 89.681501 | AB36: =SUM(R36:R37) -> 9.1522352 | AJ36: 70 | AK36: 1.7 | AL36: =(R20*$AB$10+R36*$AB$26)/$AV$26 -> 13.510145 | AM36: =((R20*S20*$AB$10+R36*S36*$AB$26)/AL36)/$AV$26 -> 39.306253 | AN36: =AL36*AM36 -> 531.03318 | AO36: =SUM($AL$27:AL36) -> 89.439281 | AP36: =SUM($AN$27:AN36) -> 2317.7759 | AQ36: =AP36/AO36 -> 25.914518 | AR36: =SUM(AL36:$AL$40) -> 24.070864 | AS36: =SUM(AN36:$AN$40) -> 1145.3784 | AT36: =AS36/AR36 -> 47.5836 | AU36: =AO36-AL36/2 -> 82.684208 | AV36: =SUM(AL36:AL37) -> 16.207561
E37: =F36 -> 1.7 | F37: 1.8 | G37: 44.2 | H37: =G37/$G$41*100 -> 1.4834206 | I37: 46.87 | J37: 0.98 | K37: 16.9 | L37: 0.39 | M37: 0.5 | N37: =1/Q37 -> 0.55555556 | P37: 77 | Q37: 1.8 | R37: =H37 -> 1.4834206 | S37: =I37*100/(100-J37) -> 47.333872 | T37: =R37*S37 -> 70.21604 | U37: =SUM($R$27:R37) -> 94.999329 | V37: =SUM($T$27:T37) -> 2305.6606 | W37: =V37/U37 -> 24.270283 | X37: =SUM(R37:$R$40) -> 6.4840918 | Y37: =SUM(T37:$T$40) -> 382.04008 | Z37: =Y37/X37 -> 58.919598 | AA37: =U37-R37/2 -> 94.257618 | AB37: =SUM(R37:R38) -> 3.4669083 | AJ37: 77 | AK37: 1.8 | AL37: =(R21*$AB$10+R37*$AB$26)/$AV$26 -> 2.6974164 | AM37: =((R21*S21*$AB$10+R37*S37*$AB$26)/AL37)/$AV$26 -> 44.331987 | AN37: =AL37*AM37 -> 119.58183 | AO37: =SUM($AL$27:AL37) -> 92.136697 | AP37: =SUM($AN$27:AN37) -> 2437.3577 | AQ37: =AP37/AO37 -> 26.453713 | AR37: =SUM(AL37:$AL$40) -> 10.560719 | AS37: =SUM(AN37:$AN$40) -> 614.3452 | AT37: =AS37/AR37 -> 58.172667 | AU37: =AO37-AL37/2 -> 90.787989 | AV37: =SUM(AL37:AL38) -> 4.7926266
E38: =F37 -> 1.8 | F38: 2 | G38: 59.1 | H38: =G38/$G$41*100 -> 1.9834877 | I38: 54.45 | J38: 1.89 | K38: 17.36 | L38: 0.51 | M38: 0 | N38: =1/Q38 -> 0.5 | P38: 84 | Q38: 2 | R38: =H38 -> 1.9834877 | S38: =I38*100/(100-J38) -> 55.49893 | T38: =R38*S38 -> 110.08145 | U38: =SUM($R$27:R38) -> 96.982816 | V38: =SUM($T$27:T38) -> 2415.7421 | W38: =V38/U38 -> 24.90897 | X38: =SUM(R38:$R$40) -> 5.0006712 | Y38: =SUM(T38:$T$40) -> 311.82404 | Z38: =Y38/X38 -> 62.356437 | AA38: =U38-R38/2 -> 95.991073 | AJ38: 84 | AK38: 2 | AL38: =(R22*$AB$10+R38*$AB$26)/$AV$26 -> 2.0952102 | AM38: =((R22*S22*$AB$10+R38*S38*$AB$26)/AL38)/$AV$26 -> 52.688466 | AN38: =AL38*AM38 -> 110.39341 | AO38: =SUM($AL$27:AL38) -> 94.231907 | AP38: =SUM($AN$27:AN38) -> 2547.7511 | AQ38: =AP38/AO38 -> 27.037032 | AR38: =SUM(AL38:$AL$40) -> 7.8633027 | AS38: =SUM(AN38:$AN$40) -> 494.76337 | AT38: =AS38/AR38 -> 62.920554 | AU38: =AO38-AL38/2 -> 93.184302
E39: =F38 -> 2 | F39: 2.2 | G39: 30.2 | H39: =G39/$G$41*100 -> 1.0135589 | I39: 56.47 | J39: 1.78 | K39: 20.79 | L39: 0.59 | M39: 0 | N39: =1/Q39 -> 0.45454545 | P39: 91 | Q39: 2.2 | R39: =H39 -> 1.0135589 | S39: =I39*100/(100-J39) -> 57.493382 | T39: =R39*S39 -> 58.272927 | U39: =SUM($R$27:R39) -> 97.996375 | V39: =SUM($T$27:T39) -> 2474.015 | W39: =V39/U39 -> 25.245985 | X39: =SUM(R39:$R$40) -> 3.0171835 | Y39: =SUM(T39:$T$40) -> 201.7426 | Z39: =Y39/X39 -> 66.864543 | AA39: =U39-R39/2 -> 97.489596 | AJ39: 91 | AK39: 2.2 | AL39: =(R23*$AB$10+R39*$AB$26)/$AV$26 -> 1.8335523 | AM39: =((R23*S23*$AB$10+R39*S39*$AB$26)/AL39)/$AV$26 -> 60.290356 | AN39: =AL39*AM39 -> 110.54552 | AO39: =SUM($AL$27:AL39) -> 96.06546 | AP39: =SUM($AN$27:AN39) -> 2658.2966 | AQ39: =AP39/AO39 -> 27.671721 | AR39: =SUM(AL39:$AL$40) -> 5.7680925 | AS39: =SUM(AN39:$AN$40) -> 384.36995 | AT39: =AS39/AR39 -> 66.637273 | AU39: =AO39-AL39/2 -> 95.148684
E40: =F39 -> 2.2 | F40: 2.8 | G40: 59.7 | H40: =G40/$G$41*100 -> 2.0036246 | I40: 70.71 | J40: 1.25 | K40: 18.82 | L40: 0.065 | M40: 0 | N40: =1/Q40 -> 0.35714286 | P40: 98 | Q40: 2.8 | R40: =H40 -> 2.0036246 | S40: =I40*100/(100-J40) -> 71.605063 | T40: =R40*S40 -> 143.46967 | U40: =SUM($R$27:R40) -> 100 | V40: =SUM($T$27:T40) -> 2617.4847 | W40: =V40/U40 -> 26.174847 | X40: =SUM(R40:$R$40) -> 2.0036246 | Y40: =SUM(T40:$T$40) -> 143.46967 | Z40: =Y40/X40 -> 71.605063 | AA40: =U40-R40/2 -> 98.998188 | AJ40: 98 | AK40: 2.8 | AL40: =(R24*$AB$10+R40*$AB$26)/$AV$26 -> 3.9345402 | AM40: =((R24*S24*$AB$10+R40*S40*$AB$26)/AL40)/$AV$26 -> 69.595027 | AN40: =AL40*AM40 -> 273.82443 | AO40: =SUM($AL$27:AL40) -> 100 | AP40: =SUM($AN$27:AN40) -> 2932.1211 | AQ40: =AP40/AO40 -> 29.321211 | AR40: =SUM(AL40:$AL$40) -> 3.9345402 | AS40: =SUM(AN40:$AN$40) -> 273.82443 | AT40: =AS40/AR40 -> 69.595027 | AU40: =AO40-AL40/2 -> 98.03273
B41: Total | G41: =SUM(G27:G40) -> 2979.6 | H41: =SUM(H27:H40) -> 100 | I41: =SUMPRODUCT($H$27:$H$40,I27:I40)/$H$41 -> 25.945711 | J41: =SUMPRODUCT($H$27:$H$40,J27:J40)/$H$41 -> 0.82325413 | K41: =SUMPRODUCT($H$27:$H$40,K27:K40)/$H$41 -> 20.730855 | L41: =SUMPRODUCT($H$27:$H$40,L27:L40)/$H$41 -> 0.52649836 | M41: =SUMPRODUCT($H$27:$H$40,M27:M40)/$H$41 -> 2.5615015
...

Sheet Froth Flotation
B1: Sample Name: | D1: ='[1]Raw Coal analysis'!C1 -> PR8_B35_4AL_01-08
B2: Sample Description: | D2: -0.25мм Froth Flotation
B3: Reported date:
B4: Reported to:
B5: Sampled date:
B7: Size Fraction, mm | D7: Mass % of overall | E7: Fractional | L7: Cum Floats
E8: Mass | G8: Ash, dry | H8: Q of mass, | I8: IM, | J8: Vol, % ad | K8: CSN | L8: Mass, | M8: Q of mass, | N8: Ash, dry
E9: gram | F9: (%) | G9: (%) | H9: (%) | I9: (%) | J9: (%) | L9: (%) | M9: (%) | N9: (%)
B10: -0.25 | C10: +0 | D10: =Pretreatment!R48+Pretreatment!R49+Pretreatment!R50+Pretreatment!R51 -> 9.623431
D11: C1 | E11: 145.6 | F11: =E11/$E$17*100 -> 41.683367 | G11: 11.8 | H11: =F11*G11 -> 491.86373 | I11: 0.9 | J11: 25.84 | K11: 7 | L11: =SUM($F$11:F11) -> 41.683367 | M11: =SUM($H$11:H11) -> 491.86373 | N11: =M11/L11 -> 11.8
D12: C2 | E12: 90.8 | F12: =E12/$E$17*100 -> 25.994847 | G12: 13.21 | H12: =F12*G12 -> 343.39193 | I12: 0.85 | J12: 25.18 | K12: 7 | L12: =SUM($F$11:F12) -> 67.678214 | M12: =SUM($H$11:H12) -> 835.25565 | N12: =M12/L12 -> 12.341574
D13: C3 | E13: 65.2 | F13: =E13/$E$17*100 -> 18.665903 | G13: 14.91 | H13: =F13*G13 -> 278.30862 | I13: 0.86 | J13: 25.99 | K13: 7 | L13: =SUM($F$11:F13) -> 86.344117 | M13: =SUM($H$11:H13) -> 1113.5643 | N13: =M13/L13 -> 12.896817
D14: C4 | E14: 3.4 | F14: =E14/$E$17*100 -> 0.97337532 | G14: 32.46 | H14: =F14*G14 -> 31.595763 | I14: 0.93 | J14: 23 | K14: 0 | L14: =SUM($F$11:F14) -> 87.317492 | M14: =SUM($H$11:H14) -> 1145.16 | N14: =M14/L14 -> 13.114898
D15: T1 | E15: 40 | F15: =E15/$E$17*100 -> 11.451474 | G15: 62.93 | H15: =F15*G15 -> 720.64128 | I15: 1.02 | J15: 21.75 | K15: 0 | L15: =SUM($F$11:F15) -> 98.768967 | M15: =SUM($H$11:H15) -> 1865.8013 | N15: =M15/L15 -> 18.890562
D16: T2 | E16: 4.3 | F16: =E16/$E$17*100 -> 1.2310335 | G16: 74.65 | H16: =F16*G16 -> 91.89665 | I16: 1.01 | J16: 20.75 | K16: 0 | L16: =SUM($F$11:F16) -> 100 | M16: =SUM($H$11:H16) -> 1957.698 | N16: =M16/L16 -> 19.57698
B17: Total | E17: =SUM(E11:E16) -> 349.3 | F17: =SUM(F11:F16) -> 100

Sheet Composite Product Analysis 
B1: Sample Name:
B2: Sample Description:
B3: Reported date:
B4: Reported to:
B5: Sampled date:
B8: Sample ID | C8: Sample Name_Composite Product
B9: Initial Mass, kg
B10: TM, %
B11: IM, % | C11: -
B12: Ash, ad % | C12: -
B13: Vol, ad, %
B14: CSN,
B15: G index
B16: Sulphur, ad %
B17: TRD
B20: Petrograph
B21: Mean Maximum Reflactance (RoMax )
B22: Random Reflactance
B24: Vitrinite
B25: Liptinite
B26: Inertinite

Sheet Summary 
A1: Washability summary
A2: Size | B2: Wt % of overall | C2: Float SG | D2: Yield % | E2: Ash %
A3: -50 x 8mm | B3: ='Float sink'!AV26 -> 39.539749 | C3: 2 | D3: 5 | E3: 12
A4: 8 x 2mm | B4: ='Float sink'!AV42 -> 30.753138 | C4: 1.47 | D4: 37 | E4: 12
A5: 2 x 0.250mm | B5: ='Float sink'!AV58 -> 20.083682 | C5: 1.8 | D5: 19 | E5: 3.8
A6: 0.250mm x 0 | B6: ='Froth Flotation'!D10 -> 9.623431 | D6: 41.68 | E6: 11.8
A7: Total | B7: =SUM(B3:B6) -> 100 | D7: =SUMPRODUCT(B3:B6,D3:D6)/B7 -> 21.182594 | E7: =SUMPRODUCT(B3:B6,D3:D6,E3:E6)/SUMPRODUCT(B3:B6,D3:D6) -> 10.484955
A9: LIMN Simulation
A11: UHG 2019 Blend - 100% 4AL
A13: Coking Product | B13: 855
B14: TPH (ad) | C14: Ash (dry) | D14: Surface Moisture | E14: Total Moisture | F14: TPH (ar) | G14: Ash (ar) | H14: Ash (ad) | I14: Volatiles (ad) | J14: Sulphur (ad) | K14: CSN | L14: kcal/kg (ar)
A15: Coarse Coal Product | B15: 117.84756 | C15: 12.426325 | D15: 3 | E15: 3.6305 | F15: 121.49233 | G15: 11.975187 | H15: 12.345554 | J15: 29.470782 | K15: 5.791222 | L15: 0 | M15: =B15/B13 -> 0.13783341
A16: 13c Fine Coal Product | B16: 3.3911645 | C16: 9.2465528 | D16: 12 | E16: 12.572 | F16: 3.8535961 | G16: 8.0840762 | H16: 9.1864502 | J16: 29.663922 | K16: 6.9373369 | L16: 0 | M16: =B16/B13 -> 0.0039662743
A17: 17 Ultra Fine Product | B17: 55.264582 | C17: 7.7825113 | D17: 25 | E17: 25.4875 | F17: 73.686109 | G17: 5.7989437 | H17: 7.7319249 | J17: 29.762463 | K17: 7.3860112 | L17: 0 | M17: =B17/B13 -> 0.064636938
A18: Coking Product | B18: 176.50331 | C18: 10.911217 | D18: 11.319147 | E18: 11.895572 | F18: 199.03204 | G18: 9.6132653 | H18: 10.840294 | J18: 29.56582 | K18: 6.3125835 | L18: 0
A19: Primary Product Yield | B19: 0.20643662
A22: Middlings/Thermal Secondary Product
B23: TPH (ad) | C23: Ash (dry) | D23: Surface Moisture | E23: Total Moisture | F23: TPH (ar) | G23: Ash (ar) | H23: Ash (ad) | I23: Volatiles (ad) | J23: Sulphur (ad) | K23: CSN | L23: kcal/kg (ar)
A24: Middlings Product | B24: 249.96553 | C24: 24.930803 | D24: 3 | E24: 3.6305 | F24: 257.69643 | G24: 24.025691 | H24: 24.768753 | J24: 27.078311 | K24: 1.8703965 | L24: 0
A25: Secondary Product Yield | B25: 0.29235735
A27: Inherent Moisture | D27: 0.65
A30: Ash-Yield Equation
B32: ROM ash, % | C32: Yield, %
B33: 26.22 | C33: 0.206
B34: 17.764287 | C34: 0.79049598
B35: 20.188049 | C35: 0.74833329
B36: 22.283153 | C36: 0.71150719
B37: 24.126709 | C37: 0.67883533
B38: 25.771404 | C38: 0.64949002
